Workbook
Name Comprar: [1]Param!#REF!
Name Comprar: [1]Param!#REF!
Name Comprar: [1]Param!#REF!
Name Comprar: [1]Param!#REF!
Name Comprar: [1]Param!#REF!
Name Comprar: [2]param!#REF!
Name Início_do_projeto: '[3]Gráfico de Gantt'!$G$5
Name Início_do_projeto: '[3]Gráfico de Gantt'!$G$5
Name Início_do_projeto: '[3]Gráfico de Gantt'!$G$5
Name Início_do_projeto: '[3]Gráfico de Gantt'!$G$5
Name Início_do_projeto: '[3]Gráfico de Gantt'!$G$5
Name Início_do_projeto: '[4]Gráfico de Gantt'!$G$5
Name Periodicidade: [5]Param!$AB$5:$AB$9
Name Semana_de_exibição: '[3]Gráfico de Gantt'!$G$6
Name Semana_de_exibição: '[3]Gráfico de Gantt'!$G$6
Name Semana_de_exibição: '[3]Gráfico de Gantt'!$G$6
Name Semana_de_exibição: '[3]Gráfico de Gantt'!$G$6
Name Semana_de_exibição: '[3]Gráfico de Gantt'!$G$6
Name Semana_de_exibição: '[4]Gráfico de Gantt'!$G$6
Name Status: [1]Param!#REF!
Name Status: [1]Param!#REF!
Name Status: [1]Param!#REF!
Name Status: [1]Param!#REF!
Name Status: [1]Param!#REF!
Name Status: [2]param!#REF!
Name VersaoExcel: [5]Param!$D$15:$E$15
Name VersaoSR: [5]Param!$C$24:$C$26

Sheet Project Charter
B1: Componentes do grupo:
B2: 1) Anie Augusto Bissoli RA: 24025800
B3: 2) Bruna Farias Pires RA:24026043
B4: 3) Erika Santana da Silva RA:24026205
B5: 4) Luiza Domingues Chaveiro Correia RA:24025990

Sheet WBS-MACRO-ATIVIDADE

Sheet WBS_Detalhado (ordem etapas)
B7: 4.1 Plano de ação detalhado da WBS (com dependência, tempo e recurso) | P7: FAREMOS MAIS PARA FRENTE
B9: Ref | C9: Etapas – Atividades - | D9: Dependência | E9: Data Início | F9: Data Fim | G9: Duração em dias | H9: Conclusão | I9: Responsável | J9: Recursos | K9: Custos | L9: Obs | O9: Rede de Precedência de Atividades
B10: 1 | C10: Iniciação | D10: 1 | P10: Atividades | Q10: Dependência | R10: Duração em semanas
B11: 1.1 | C11: Definir objetivos do dashboard | D11: 1.1 | E11: 45884 | F11: 45885 | G11: =F11-E11 -> 1 | H11: 2ª | I11: GERENTE DE PROJETO | J11: Pessoas | K11: 2500 | O11: 1 | P11: Iniciação | Q11: NÃO | R11: 6
B12: 1.2 | C12: Levantamento de necessidades com Cannoli e clientes | D12: 1.1 | E12: 45885 | F12: 45886 | G12: =F12-E12 -> 1 | H12: 2ª | I12: GERENTE DE PROJETO | J12: Pessoas | K12: 2000 | O12: 2 | P12: Planejamento | Q12: Iniciação | R12: 11
B13: 1.3 | C13: Formar uma equipe de desenvolvimento | D13: 1.2 | E13: 45886 | F13: 45887 | G13: =F13-E13 -> 1 | H13: 2ª | I13: GERENTE DE PROJETO | J13: Pessoas | K13: 3200 | O13: 3 | P13: Design e Prototipagem | Q13: Iniciação | R13: 8
B14: 2 | C14: Planejamento | D14: 1.3 | K14: =SUM(K11:K13) -> 7700 | O14: 4 | P14: Desenvolvimento | Q14: Planejamento/Design e Prototipagem | R14: 11
B15: 2.1 | C15: Realizar uma análise de mercado para entender concorrentes e demandas | D15: 2.1 | E15: 45888 | F15: 45889 | G15: =F15-E15 -> 1 | H15: 2ª | I15: GERENTE DE PROJETO | J15: Pessoas | K15: 2000 | O15: 5 | P15: Integração com sistemas de monitoramento de saúde | Q15: Desenvolvimento | R15: 5
B16: 2.2 | C16: Definir KPIs e métricas principais para administradores e clientes | D16: 1.2 | E16: 45889 | F16: 45891 | G16: =F16-E16 -> 2 | H16: 2ª | I16: GERENTE DE PROJETO | J16: Pessoas | K16: 2500 | O16: 6 | P16: Testes | Q16: Integração com sistemas de monitoramento de saúde | R16: 3
B17: 2.2.1 | C17: Definir filtros, gráficos interativos e painéis | D17: 2.2 | E17: 45889 | F17: 45891 | G17: =F17-E17 -> 2 | H17: 2ª | I17: GERENTE DE PROJETO | J17: Pessoas | K17: 2500 | O17: 7 | P17: Lançamento (Stakeholders internos) | Q17: Testes | R17: 6
B18: 2.2.2 | C18: Planejar alertas inteligentes e sugestões automáticas | D18: 2.2 | E18: 45893 | F18: 45896 | G18: =F18-E18 -> 3 | H18: 1ª | I18: GERENTE DE PROJETO | J18: Pessoas | K18: 2500 | O18: 8 | P18: Pós-lançamento (Stakeholders internos) | Q18: Lançamento (Stakeholders internos) | R18: 6
B19: 2.2.3 | C19: Definir integração com banco de dados e atualização de dados | D19: 2.2 | E19: 45893 | F19: 45896 | G19: =F19-E19 -> 3 | H19: 1ª | I19: GERENTE DE PROJETO | J19: Pessoas | K19: 2500 | O19: 9 | P19: Marketing e Divulgação para o Mercado | Q19: Pós-lançamento (Stakeholders internos) | R19: 6
B20: 3 | C20: Design e Prototipagem | D20: 2.2.5 | K20: =SUM(K15:K19) -> 12000 | O20: 10 | P20: Avaliação e Aperfeiçoamento | Q20: Marketing e Divulgação | R20: 6
B21: 3.1 | C21: Realizar o design da interface do dashboard | D21: 1.3 | E21: 45899 | F21: 45901 | G21: =F21-E21 -> 2 | H21: 1ª | I21: DESIGN | J21: Pessoas | K21: 2000 | O21: 11 | P21: Expansão | Q21: Avaliação e Aperfeiçoamento | R21: 6
B22: 3.1.1 | C22: Navegação simples entre módulos de análise (KPIs, gráficos, alertas) | D22: 3.1 | E22: 45899 | F22: 45901 | G22: =F22-E22 -> 2 | H22: 1ª | I22: DESIGN | J22: Pessoas | K22: 2250
B23: 3.1.2 | C23: Criar protótipos interativos para validação do fluxo de usuário | D23: 3.1.1 | E23: 45901 | F23: 45904 | G23: =F23-E23 -> 3 | H23: 1ª | I23: DESIGN | J23: Pessoas | K23: 2200
B24: 3.2 | C24: Experiência do usuário (UX) | D24: 3.1.2 | E24: 45904 | F24: 45906 | G24: =F24-E24 -> 2 | H24: 1ª | I24: DESIGN | J24: Pessoas | K24: 2250
B25: 3.2.1 | C25: Interface limpa e intuitiva para admins e clientes | D25: 3.2 | E25: 45907 | F25: 45908 | G25: =F25-E25 -> 1 | H25: 2ª | I25: DESIGN | J25: Pessoas | K25: 2250
B26: 3.2.2 | C26: Teste de usabilidade UI/UX com usuários reais ou simulados | D26: 3.2 | E26: 45910 | F26: 45911 | G26: =F26-E26 -> 1 | H26: 2ª | I26: DESIGN | J26: Pessoas | K26: 2250
B27: 4 | C27: Desenvolvimento | D27: 3.2.2 | K27: =SUM(K21:K26) -> 13200
B28: 4.1 | C28: Desenvolver a estrutura do dashboard | D28: 4.1 | E28: 45913 | F28: 45917 | G28: =F28-E28 -> 4 | H28: 2ª | I28: DESENVOLVIMENTO | J28: Pessoas | K28: 6000
B29: 4.1.2 | C29: Criar gráficos interativos (vendas, campanhas, perfil de clientes) | D29: 4.1 | E29: 45915 | F29: 45917 | G29: =F29-E29 -> 2 | H29: 1ª | I29: DESENVOLVIMENTO | J29: Pessoas | K29: 4000
B30: 4.1.3 | C30: Codificação back-end | D30: 4.1 | E30: 45913 | F30: 45917 | G30: =F30-E30 -> 4 | H30: 2ª | I30: DESENVOLVIMENTO | J30: Pessoas | K30: 4500
B31: 4.2 | C31: Implementar APIs para consulta de dados de clientes, pedidos e campanhas | D31: 2.2 | E31: 45913 | F31: 45917 | G31: =F31-E31 -> 4 | H31: 1ª | I31: DESENVOLVIMENTO | J31: Pessoas | K31: 4000
B32: 4.2.1 | C32: Configurar autenticação de usuários (admin e clientes) | D32: 4.2 | E32: 45913 | F32: 45917 | G32: =F32-E32 -> 4 | H32: 2ª | I32: DESENVOLVIMENTO | J32: Pessoas | K32: 4000
B33: 4.2.2 | C33: Notificações sobre variações significativas em vendas ou engajamento | D33: 4.2 | E33: 45913 | F33: 45917 | G33: =F33-E33 -> 4 | H33: 1ª | I33: DESENVOLVIMENTO | J33: Pessoas | K33: 4000
B34: 4.2.3 | C34: Exportação de relatórios | D34: 4.2 | E34: 45913 | F34: 45917 | G34: =F34-E34 -> 4 | H34: 2ª | I34: DESENVOLVIMENTO | J34: Pessoas | K34: 5500
B35: 5 | C35: Integração com sistemas de monitoramento de saúde | D35: 4.2.3 | K35: =SUM(K28:K34) -> 32000
B36: 5.1 | C36: Importar dados de clientes, pedidos e campanhas de parceiros | D36: 5.1 | E36: 45917 | F36: 45921 | G36: =F36-E36 -> 4 | H36: 2ª | I36: SEGURANÇA | J36: Pessoas | K36: 3000
B37: 5.2 | C37: Garantir a segurança e privacidade dos dados do usuário | D37: 5.2 | E37: 45917 | F37: 45921 | G37: =F37-E37 -> 4 | H37: 2ª | I37: SEGURANÇA | J37: Pessoas | K37: 1000
B38: 5.3 | C38: Garantir sincronização correta de dados entre front-end e back-end | D38: 5.0 | E38: 45917 | F38: 45921 | G38: =F38-E38 -> 4 | H38: 1° | I38: SEGURANÇA | J38: Pessoas | K38: 1000
B39: 5.4 | C39: Controle de acesso por perfil (admin e cliente) | D39: 5.3 | E39: 45917 | F39: 45921 | G39: =F39-E39 -> 4 | H39: 1ª | I39: SEGURANÇA | J39: Pessoas | K39: 1000
B40: 6 | C40: Testes | D40: 5.3
B41: 6.1 | C41: Testar usabilidade com usuários internos e clientes simulados | D41: 6.1 | E41: 45923 | F41: 45924 | G41: =F41-E41 -> 1 | H41: 1ª | I41: QUALIDADE | J41: Pessoas | K41: 7500
B42: 6.1.2 | C42: Identificar e corrigir bugs e problemas de interface | D42: 6.1.2 | E42: 45923 | F42: 45924 | G42: =F42-E42 -> 1 | H42: 1ª | I42: QUALIDADE | J42: Pessoas | K42: 2600
B43: 6.1.3 | C43: Validar filtros, gráficos e relatórios interativos | D43: 6.1.3 | E43: 45923 | F43: 45924 | G43: =F43-E43 -> 1 | H43: 1ª | I43: QUALIDADE | J43: Pessoas | K43: 1500
B44: 7 | C44: Lançamento (Stakeholders internos) | D44: 6.1.3 | K44: =SUM(K41:K43) -> 11600
B45: 7.1.1 | C45: Preparar infraestrutura para disponibilização do dashboard | D45: 7.1.1 | E45: 45923 | F45: 45924 | G45: =F45-E45 -> 1 | H45: 2ª | I45: REDES | J45: Pessoas | K45: 7500
B46: 7.1.3 | C46: Validar acesso com usuários teste antes do lançamento oficial | D46: 7.1.3 | E46: 45923 | F46: 45924 | G46: =F46-E46 -> 1 | H46: 2ª | I46: COMERCIAL | J46: Pessoas | K46: 4500
B47: 8 | C47: Pós-lançamento (Stakeholders internos) | D47: 7.1.3 | K47: =SUM(K45:K46) -> 12000
...

Sheet WBS_Detalhado (ordem depend)
B6: 4.2 Plano de ação detalhado da WBS (com dependência, tempo e recurso)
B8: Ref | C8: Etapas – Atividades - | D8: Dependência | E8: Duração em semanas | F8: Conclusão | G8: Responsável | H8: Recursos | I8: Obs
B9: 1.1 | C9: Definir objetivos do dashboard | D9: 1.1 | E9: 2 | F9: 1ª | G9: GERENTE DE PROJETO | H9: Pessoas | I9: -
B10: 1.2 | C10: Levantamento de necessidades com Cannoli e clientes | D10: 1.1 | E10: 2 | F10: 2ª | G10: GERENTE DE PROJETO | H10: Pessoas | I10: -
B11: 1.3 | C11: Formar equipe de desenvolvimento | D11: 1.2 | E11: 2 | F11: 2ª | G11: GERENTE DE PROJETO | H11: Pessoas
B12: 2.1 | C12: Realizar uma análise de mercado para entender concorrentes e demandas | D12: 2.1 | E12: 2 | F12: 2ª | G12: GERENTE DE PROJETO | H12: Pessoas
B13: 2.2 | C13: Definir KPIs e métricas principais | D13: 1.2 | E13: 2 | F13: 2ª | G13: GERENTE DE PROJETO | H13: Pessoas
B14: 2.2.1 | C14: Definir filtros, gráficos e painéis | D14: 2.2 | E14: 2 | F14: 2ª | G14: GERENTE DE PROJETO | H14: Pessoas | I14: -
B15: 2.2.2 | C15: Planejar alertas inteligentes e sugestões | D15: 2.2 | E15: 1 | F15: 2ª | G15: GERENTE DE PROJETO | H15: Pessoas | I15: -
B16: 2.2.3 | C16: Definir integração com banco de dados | D16: 2.2 | E16: 1 | F16: 1ª | G16: GERENTE DE PROJETO | H16: Pessoas | I16: -
B17: 3.1 | C17: Realizar o design da interface do usuário (UI) | D17: 1.3 | E17: 1 | F17: 1ª | G17: DESIGN | H17: Pessoas | I17: -
B18: 3.1.1 | C18: Navegação entre módulos de análise | D18: 3.1 | E18: 1 | F18: 1ª | G18: DESIGN | H18: Pessoas | I18: -
B19: 3.1.2 | C19: Criar protótipos interativos | D19: 3.1.1 | E19: 1 | F19: 1ª | G19: DESIGN | H19: Pessoas | I19: -
B20: 3.2 | C20: Experiência do usuário (UX) | D20: 3.1.2 | E20: 1 | F20: 1ª | G20: DESIGN | H20: Pessoas | I20: -
B21: 3.2.1 | C21: Interface limpa e intuitiva | D21: 3.2 | E21: 2 | F21: 1ª | G21: DESIGN | H21: Pessoas | I21: -
B22: 3.2.2 | C22: Testes de usabilidade com usuários | D22: 3.2 | E22: 2 | F22: 2ª | G22: DESIGN | H22: Pessoas | I22: -
B23: 4.1 | C23: Desenvolver a estrutura do dashboard | D23: 4.1 | E23: 2 | F23: 2ª | G23: DESENVOLVIMENTO | H23: Pessoas | I23: -
B24: 4.1.2 | C24: Criar gráficos interativos | D24: 4.1 | E24: 1 | F24: 2ª | G24: DESENVOLVIMENTO | H24: Pessoas | I24: -
B25: 4.1.3 | C25: Codificação back-end | D25: 4.1 | E25: 2 | F25: 1ª | G25: DESENVOLVIMENTO | H25: Pessoas | I25: -
... B50: 11.1.3 | C50: Desenvolver parcerias estratégicas (restaurantes e foodtechs) | D50: 11.1.3 | E50: 2 | F50: 2ª | G50: EQUIPE TÉCNICA | H50: Pessoas | I50: -

Sheet Análise de Steakholder
A2: Entregas do Projeto | B2: A definir | C2: Atulizado Em | D2: 45901
A4: SAM | I4: SRM
A5: Stakeholder | B5: Objetivos | C5: Metas | D5: Motivações e Interesses | E5: Poder e influência | F5: Importância e Impacto | G5: Papéis & Responsabilidades | H5: Sintonia "fina" | I5: Área de Interesse | J5: Nível de Detalhe | K5: Formato | L5: Frequência | M5: Mecanismo de Entrega
A6: Cliente (Usuários Finais) | B6: Receber relatórios claros e sugestões de campanhas. | C6: Sentir-se apoiado, ter dados organizados e acionáveis. | D6: Facilidade, economia de tempo, retorno rápido. | E6: Decidem a continuidade do serviço | F6: Cruciais para mostrar valor ao restaurante. | G6: Usa o sistema pra dar feedback sobre relatórios | H6: Manter os clientes satisfeitos, garantir que o aplicativo atenda às suas necessidades. | I6: Relatórios mensais e com algum resumo automático | J6: Resumos curtos com alguns gráficos básicos | K6: Comunicar via e-mail, whatsApp | L6: Mensalmente ou imediatamente para correções críticas. | M6: E-mails de ativação, ou via WhatsApp.
A7: Product Owner | B7: Garantir que o sistema atenda às necessidades do cliente. | C7: Lançamento bem-sucedido, aumento de usuários ativos, satisfação do cliente. | D7: Sucesso do produto, inovação na área de saúde e bem-estar. | E7: Determina a direção e as prioridades do desenvolvimento. | F7: Fundamental para o sucesso do aplicativo. | G7: Definir a visão do produto, priorizar recursos, tomar decisões estratégicas. | H7: Alinhar o desenvolvimento com as necessidades dos clientes. | I7: Relatórios de desempenho do aplicativo, métricas-chave, feedback dos usuários, status do desenvolvimento. | J7: Relatórios detalhados com métricas específicas e análise de tendências. | K7: Reuniões mensais de revisão de desempenho no teams e relatórios detalhados no PBI | L7: Dailys durante a sprint e as demais reuniões do scrum. | M7: Reuniões remotas, relatórios enviados por e-mail.
A8: Desenvolvedores | B8: Criar um aplicativo funcional e confiável. | C8: Implementar recursos, manter a estabilidade, otimizar o desempenho. | D8: Desenvolvimento de software, aprendizado contínuo. | E8: Impactam diretamente na qualidade técnica do aplicativo. | F8: Contribuem para a usabilidade e confiabilidade do aplicativo. | G8: Escrever código, realizar testes, resolver problemas técnicos. | H8: Colaboração eficaz com o Product Owner para implementar recursos com sucesso. | I8: Atualizações de prioridades de desenvolvimento, correções de bugs, novos recursos planejados. | J8: Comunicados claros e específicos sobre o que precisa ser desenvolvido. | K8: Dailys e alinhamentos semanais de sprint com a equipe de desenvolvimento, UX e PO, utilizando o scrum. | L8: Dailys durante a sprint e as demais reuniões do scrum. | M8: Reuniões virtuais, quadro de tarefas online no jira.
A9: Time Comercial | B9: Vender a solução para restaurantes. | C9: Aumentar base de clientes da Cannoli. | D9: Crescimento da base de clientes, geração de receita, sucesso da solução no mercado. | E9: Apresentar solução, recolher objeções de clientes. | F9: Influenciam estratégias de vendas e entrada no mercado | G9: Apresentar solução, recolher objeções de clientes. | H9: Alinhamento com as estratégias de marketing e desenvolvimento. | I9: Informações sobre estratégias de venda, parcerias potenciais, aquisição de clientes. | J9: informações resumidas, focadas em benefícios, diferenciais e objeções comuns. | K9: Apresentações, pitchs | L9: Atualizações semanais + revisão trimestral. | M9: Reuniões virtuais, materiais de apoio por e-mail.
A10: Marketing | B10: Promover a solução e a marca Cannoli. | C10: Aumentar visibilidade, gerar leads. | D10: Mostrar benefícios, reforçar marca. | E10: Moldam percepção de mercado. | F10: Influenciam aquisição de clientes. | G10: Planejar campanhas, criar conteúdo, monitorar métricas de marketing. | H10: Alinhamento com Comercial e PO. | I10: Resultados de campanhas, público-alvo, concorrência. | J10: Informações resumidas e estratégicas, focadas em métricas de campanha, ROI, engajamento e alcance do público-alvo. | K10: Relatórios de campanhas, apresentações visuais. | L10: Mensal + conforme necessidade. | M10: Reuniões virtuais, relatórios em PPT/PBI.
A11: UX (User Experience) | B11: Melhorar a usabilidade e a experiência do usuário. | C11: Criar designs intuitivos, otimizar a navegação. | D11: Satisfação do usuário, inovação em design. | E11: Influenciam diretamente na usabilidade e na retenção de usuários. | F11: Usabilidade define aceitação. | G11: Criar protótipos, testes de usabilidade, validar design. | H11: Trabalhar próximo de Devs e PO. | I11: Experiência do usuário, relatórios visuais. | J11: Relatórios detalhados de testes de usabilidade, propostas de melhorias de design. | K11: Mockups, protótipos. | L11: Em cada sprint review e testes. | M11: Figma, Miro
A12: Equipe de Suporte ao Cliente | B12: Resolver problemas dos usuários e fornecer suporte. | C12: Resolução rápida de problemas, satisfação do cliente. | D12: Satisfação do cliente, melhoria contínua do suporte. | E12: Podem influenciar a satisfação do cliente. | F12: Mantêm os clientes satisfeitos e engajados. | G12: Responder a perguntas, resolver problemas, coletar feedback do cliente. | H12: Fornecer suporte eficaz para manter os clientes felizes. | I12: Problemas recorrentes relatados pelos usuários, solicitações de recursos. | J12: Relatórios resumidos de problemas mais frequentes, respostas a solicitações de recursos. | K12: Reuniões mensais no teams de revisão de suporte, resumos enviados por e-mail. | L12: Mensal para revisão de suporte, atualizações conforme necessário. | M12: Reuniões virtuais, e-mails informativos.
A13: Gerência Executiva/Alta Administração | B13: Alinhar o aplicativo com a visão da empresa e garantir o sucesso financeiro e da marca no mercado. | C13: Crescimento do aplicativo, alinhamento estratégico, retorno sobre o investimento. | D13: Sucesso da empresa, crescimento financeiro. | E13: Definem a estratégia e os recursos disponíveis. | F13: Determinam o curso do aplicativo e seu impacto na empresa. | G13: Estabelecer metas estratégicas, alocar recursos, tomar decisões de alto nível. | H13: Manter o alinhamento estratégico e garantir que o aplicativo contribua para os objetivos da empresa. | I13: Resultados gerais do projeto, conformidade com os objetivos estratégicos, desempenho financeiro. | J13: Relatórios de alto nível com foco em métricas-chave e alinhamento estratégico. | K13: Reuniões trimestrais no teams de revisão executiva, relatórios executivos resumidos com dados do PBI via ppt. | L13: Mensal para revisão executiva, atualizações conforme necessário. | M13: Reuniões presenciais ou virtuais, relatórios executivos enviados por e-mail.

Sheet Diagrama de Seta
A1: Projeto para construir uma casa | J1: Diagrama de seta
K2: Atividade fantasma
B3: Quantos Dias dura o projeto?
F4: Dias
A5: Desenvolvimento APP | B5: Atividade | C5: Dependência | D5: Duração | F5: 1 | G5: 2 | H5: 3 | I5: 4 | J5: 5 | K5: 6 | L5: 7 | M5: 8 | N5: 9 | O5: 10 | P5: 11 | Q5: 12 | R5: 13 | S5: 14 | T5: 15 | U5: 16 | V5: 17 | W5: 18 | X5: 19 | Y5: 20 | Z5: 21 | AA5: 22 | AB5: 23 | AC5: 24 | AD5: 25 | AE5: 26 | AF5: 27 | AG5: 28 | AH5: 29 | AI5: 30 | AJ5: 31 | AK5: 32 | AL5: 33 | AM5: 34 | AN5: 35 | AO5: 36 | AP5: 37 | AQ5: 38 | AR5: 39 | AS5: 40 | AT5: 41 | AU5: 42 | AV5: 43 | AW5: 44 | AX5: 45 | AY5: 46 | AZ5: 47 | BA5: 48 | BB5: 49 | BC5: 50 | BD5: 51
A6: Definição dos objetivos do sistema e dashboards | B6: 1.1 | C6: - | D6: 3
A7: Levantamento inicial de requisitos com a Cannoli | B7: 1.2 | C7: 1.1 | D7: 2 | L7: 2.2 | O7: 2.3 | W7: 3.4 | AF7: 4.2
A8: Análise das campanhas de fidelização da Cannoli | B8: 2.1 | C8: 1.2 | D8: 1 | F8: 1.1 | I8: 1.2 | K8: 2.1 | Q8: 2.4 | U8: 3.3 | AR8: 7.1
A9: Definição de requisitos funcionais e não funcionais | B9: 2.2 | C9: 2.1 | D9: 2 | Z9: 3.5 | AN9: 6.2 | AT9: 7.2 | AW9: 7.3 | BD9: 8.3
A10: Elaboração do cronograma e definição de metas | B10: 2.3 | C10: 2.2 | D10: 2 | S10: 3.1 | U10: 3.2 | AD10: 4.1 | AF10: 4.3 | AI10: 5.1 | AP10: 6.3 | BB10: 8.2
A11: Identificação de riscos e plano de mitigação | B11: 2.4 | C11: 2.3 | D11: 3 | AJ11: 5.2 | AL11: 6.1 | AZ11: 8.1
A12: Estrutura de navegação e fluxos de usuários | B12: 3.1 | C12: 2.4 | D12: 2
A13: Criação de protótipos visuais (dashboards e relatórios) | B13: 3.2 | C13: 3.1 | D13: 2
A14: Design de interface limpa e intuitiva | B14: 3.3 | C14: 3.1 | D14: 2
A15: Testes de usabilidade e ajustes visuais | B15: 3.4 | C15: 3.3 | D15: 1
A16: Modelagem do banco de dados (usuários, campanhas, métricas) | B16: 3.5 | C16: 3.4 | D16: 5
A17: Implementação do backend | B17: 4.1 | C17: 3.5 | D17: 2
A18: Implementação do frontend | B18: 4.2 | C18: 4.1 | D18: 2
A19: Integração com base de dados e testes iniciais | B19: 4.3 | C19: 4.2 | D19: 3
A20: Implementação de KPIs automáticos e filtros de análise | B20: 5.1 | C20: 4.3 | D20: 2
A21: Geração de relatórios mensais automáticos | B21: 5.2 | C21: 5.1 | D21: 1
A22: Testes funcionais e de performance | B22: 6.1 | C22: 5.2 | D22: 3
A23: Testes de compatibilidade e responsividade | B23: 6.2 | C23: 6.1 | D23: 1
... A30: Documentação final e suporte pós-apresentação | B30: 8.3 | C30: 8.2 | D30: 2

Sheet Diagrama de rede-precedência
A1: Projeto Elevare | G1: PDI -Primeiro dia de início | J1: UDI - Último dia de início
G2: PDT - Primeito dia de término | J2: UDT - Último dia de término
B3: Quantos Dias dura o projeto? | G3: FL-Folgas Livres | J3: 0 | K3: É o caminho crítico
G4: FT-Folgas totais
A6: descrição | B6: Atividade | C6: Dependência | D6: Duração | F6: modelo
A7: Definição dos objetivos do sistema e dashboards | B7: 1.1 | C7: - | D7: 3 | F7: atividade | G7: duração | J7: 2.1 | K7: 2 | M7: 2.2 | N7: 2 | P7: 2.3 | Q7: 2 | S7: 2.4 | T7: 3
A8: Levantamento inicial de requisitos com a Cannoli | B8: 1.2 | C8: 1.1 | D8: 2 | F8: PDI | G8: PDT | J8: 5 | K8: 6 | M8: 6 | N8: =M8+N7 -> 8 | P8: 8 | Q8: =P8+Q7 -> 10 | S8: =MAX(K8,Q8,L21) -> 17 | T8: =S8+T7 -> 20
A9: Análise das campanhas de fidelização da Cannoli | B9: 2.1 | C9: 1.2 | D9: 1 | F9: UDI | G9: UDT | J9: 3 | K9: 6 | M9: =N9-N7 -> 6 | N9: =N8 -> 8 | P9: =Q9-Q7 -> 15 | Q9: =S9 -> 17 | S9: =T9-T7 -> 17 | T9: =T8 -> 20
A10: Definição de requisitos funcionais e não funcionais | B10: 2.2 | C10: 2.1 | D10: 2 | F10: FL | G10: FT | J10: =J9-J8 -> -2 | K10: =K9-K8 -> 0 | M10: =M9-M8 -> 0 | N10: =N9-N8 -> 0 | P10: =P9-P8 -> 7 | Q10: =Q9-Q8 -> 7 | S10: =S9-S8 -> 0 | T10: =T9-T8 -> 0
A11: Elaboração do cronograma e definição de metas | B11: 2.3 | C11: 2.2 | D11: 2
A12: Identificação de riscos e plano de mitigação | B12: 2.4 | C12: 2.3 | D12: 3
A13: Estrutura de navegação e fluxos de usuários | B13: 3.1 | C13: 2.4 | D13: 2 | F13: 1.1 | G13: 3 | I13: 1.2 | J13: 2 | P13: 3.1 | Q13: 2 | U13: 3.2 | V13: 2
A14: Criação de protótipos visuais (dashboards e relatórios) | B14: 3.2 | C14: 3.1 | D14: 2 | F14: 0 | G14: 3 | I14: 5 | J14: 5 | P14: 13 | Q14: =P14+Q13 -> 15 | U14: 15 | V14: =U14+V13 -> 17
A15: Design de interface limpa e intuitiva | B15: 3.3 | C15: 3.1 | D15: 2 | F15: 0 | G15: 6 | I15: 3 | J15: 5 | P15: =Q15-Q13 -> 13 | Q15: =Q14 -> 15 | U15: 49 | V15: 51
A16: Testes de usabilidade e ajustes visuais | B16: 3.4 | C16: 3.3 | D16: 1 | F16: =F15-F14 -> 0 | G16: =G15-G14 -> 3 | I16: =I15-I14 -> -2 | J16: =J15-J14 -> 0 | P16: =P15-P14 -> 0 | Q16: =Q15-Q14 -> 0 | U16: =U15-U14 -> 34 | V16: =V15-V14 -> 34
A17: Modelagem do banco de dados (usuários, campanhas, métricas) | B17: 3.5 | C17: 3.4 | D17: 5
A18: Implementação do backend | B18: 4.1 | C18: 3.5 | D18: 2
A19: Implementação do frontend | B19: 4.2 | C19: 4.1 | D19: 2
A20: Integração com base de dados e testes iniciais | B20: 4.3 | C20: 4.2 | D20: 3 | K20: 3.3 | L20: 3 | N20: 3.4 | O20: 2 | Q20: 3.5 | R20: 2
A21: Implementação de KPIs automáticos e filtros de análise | B21: 5.1 | C21: 4.3 | D21: 2 | K21: 15 | L21: 17 | N21: 17 | O21: 18 | Q21: 18 | R21: 23
A22: Geração de relatórios mensais automáticos | B22: 5.2 | C22: 5.1 | D22: 1 | K22: 15 | L22: =S9 -> 17 | N22: 17 | O22: 18 | Q22: 18 | R22: =R21 -> 23
A23: Testes funcionais e de performance | B23: 6.1 | C23: 5.2 | D23: 3 | K23: =K22-K21 -> 0 | L23: =L22-L21 -> 0 | N23: =N22-N21 -> 0 | O23: =O22-O21 -> 0 | Q23: =Q22-Q21 -> 0 | R23: =R22-R21 -> 0
A24: Testes de compatibilidade e responsividade | B24: 6.2 | C24: 6.1 | D24: 1
A25: Testes de segurança e conformidade com LGPD | B25: 6.3 | C25: 6.2 | D25: 2
A26: Preparação da infraestrutura para implantação | B26: 7.1 | C26: 6.3 | D26: 3 | N26: 4.1 | O26: 2 | Q26: 4.2 | R26: 2 | T26: 4.3 | U26: 3
A27: Criação de materiais de apresentação (vídeo, banner, pitch) | B27: 7.2 | C27: 7.1 | D27: 2 | N27: 23 | O27: =N27+O26 -> 25 | Q27: 25 | R27: 27 | T27: 27 | U27: =T27+U26 -> 30
A28: Entrega da versão para professores e avaliação | B28: 7.3 | C28: 7.2 | D28: 1 | N28: 23 | O28: =O27 -> 25 | Q28: 25 | R28: 27 | T28: =U28-U26 -> 27 | U28: =U27 -> 30
A29: Ajustes com base em feedbacks | B29: 8.1 | C29: 7.3 | D29: 3 | O29: =O28-O27 -> 0 | T29: =T28-T27 -> 0 | U29: =U28-U27 -> 0
A30: Entrega oficial da versão final | B30: 8.2 | C30: 8.1 | D30: 1
A31: Documentação final e suporte pós-apresentação | B31: 8.3 | C31: 8.2 | D31: 2
Q32: 5.1 | R32: 2 | T32: 5.2 | U32: 1 | W32: 6.1 | X32: 3 | Z32: 6.2 | AA32: 1 | AC32: 6.3 | AD32: 2 | AG32: 7.1 | AH32: 3 | AK32: 7.2 | AL32: 1 | AO32: 7.3 | AP32: 2
Q33: 30 | R33: 32 | T33: 32 | U33: =T33+U32 -> 33 | W33: 33 | X33: =W33+X32 -> 36 | Z33: 36 | AA33: =Z33+AA32 -> 37 | AC33: 37 | AD33: =AC33+AD32 -> 39 | AG33: 39 | AH33: =AG33+AH32 -> 42 | AK33: 42 | AL33: 44 | AO33: 44 | AP33: 45
Q34: 30 | R34: 32 | T34: 32 | U34: 33 | W34: 33 | X34: =X33 -> 36 | Z34: 36 | AA34: =AA33 -> 37 | AC34: 37 | AD34: =AD33 -> 39 | AG34: 39 | AH34: =AH33 -> 42 | AK34: 42 | AL34: 44 | AO34: 44 | AP34: 45
Q35: =Q34-Q33 -> 0 | R35: =R34-R33 -> 0 | T35: =T34-T33 -> 0 | U35: =U34-U33 -> 0 | X35: =X34-X33 -> 0 | AA35: =AA34-AA33 -> 0 | AD35: =AD34-AD33 -> 0 | AH35: =AH34-AH33 -> 0 | AL35: =AL34-AL33 -> 0 | AP35: =AP34-AP33 -> 0
AJ39: 8.1 | AK39: 3 | AM39: 8.2 | AN39: 1 | AP39: 8.3 | AQ39: 2
AJ40: 45 | AK40: =AJ40+AK39 -> 48 | AM40: 48 | AN40: =AM40+AN39 -> 49 | AP40: 49 | AQ40: =AP40+AQ39 -> 51
AJ41: 45 | AK41: =AK40 -> 48 | AM41: 48 | AN41: =AN40 -> 49 | AP41: 49 | AQ41: =AQ40 -> 51
AK42: =AK41-AK40 -> 0 | AN42: =AN41-AN40 -> 0 | AP42: 0 | AQ42: =AQ41-AQ40 -> 0

Sheet Capa
B5: Informações sobre o projeto
B6: Projeto | E6: Elevare
B7: Gerente Responsável | E7: Gerente do projeto
B8: Data da avaliação | E8: dd/mm/aaaa
B9: Histórico da avaliação de riscos
B10: dd/mm/aaaa | C10: Comentário

Sheet Identificar
A1: Identificação dos Riscos
A2: Elevare
A3: ID | B3: Fase ou | D3: Declaração do Risco | G3: Resp. | H3: Estratégia de Resposta | I3: Plano de Prevenção | J3: Plano de Contingência | K3: Riscos Colaterais | L3: Severidade (X,Y) | O3: Probabilidade | R3: Impacto
B4: Recurso | C4: Classificação | D4: CAUSA | E4: RISCO | F4: CONSEQUÊNCIA | O4: Muito Baixa - 1 | P4: 1 | R4: Muito Baixo - 1 | S4: 1
A5: R01 | B5: Pessoas | C5: Ausência | D5: Como resultado da ausência de membros chave da equipe (ex: Gerente de Projeto ou Desenvolvedores) | E5: Pode ocorrer atrasos nas etapas de planejamento e desenvolvimento | F5: O que acarretaria no lançamento do projeto | G5: Gerência | H5: Mitigar | I5: Implementar cross-training | J5: Contratar substitutos temporários | K5: Atraso no projeto e aumento nos custos | L5: 0.08 | O5: Baixa - 2 | P5: 2 | R5: Muito Baixo - 2 | S5: 2
A6: R02 | B6: Pessoas | C6: Falta de habilidade | D6: Como resultado da falta de expertise em integração com sistemas | E6: Pode ocorrer falhas na integração de dados | F6: O que acarretaria a falta de sincronização de dados entre front-end e back-end, comprometendo a usabilidade | G6: Desenvolvedores | H6: Mitigar | I6: Contratar desenvolvedores especializados | J6: Realizar treinamentos acelerados | K6: Atraso no projeto e aumento nos custos | L6: 0.16 | O6: Moderada - 3 | P6: 3 | R6: Baixo - 3 | S6: 3
A7: R03 | B7: Pessoas | C7: Expectativas | D7: Como resultado de desalinhamento de expectativas com stakeholders | E7: Pode ocorrer mudanças frequentes nos requisitos | F7: O que acarretaria no re-trabalho no design e desenvolvimento, aumentando custos e prazos | G7: Gerência | H7: Mitigar | I7: Realizar reuniões de alinhamento regulares | J7: Documentar mudanças e priorizar via PO | K7: Atraso no projeto e aumento nos custos | L7: 0.08 | O7: Alta - 4 | P7: 4 | R7: Baixo - 4 | S7: 4
A8: R04 | B8: Equipamentos | C8: Roubos | D8: Como resultado de roubo ou perda de equipamentos de desenvolvimento | E8: Pode ocorrer interrupção no desenvolvimento | F8: O que acarretaria com a equipe não prosseguindo com codificação e testes até reposição | G8: Desenvolvedores | H8: Transferir | I8: Seguros e backups em cloud e versões do codigo no github | J8: Fornecer equipamentos de backup | K8: Atraso no projeto e aumento nos custos | L8: 0.04 | O8: Moderada | P8: 3 | R8: Alta | S8: 4
A9: R05 | B9: Equipamentos | C9: Quebras | D9: Como resultado de falha técnica em servidores ou ferramentas de desenvolvimento | E9: Pode ocorrer downtime durante o desenvolvimento e testes | F9: O que acarretaria em atrasos em etapas críticas como integração e testes | G9: Gerência | H9: Evitar | I9: Manutenção preventiva em servidores | J9: Migrar para provedores redundantes | K9: Atraso no projeto e aumento nos custos | L9: 0.08 | O9: Alta | P9: 4 | R9: Alta | S9: 4
A10: R06 | B10: Equipamentos | C10: Defeito | D10: Como resultado de defeitos em softwares de terceiros (ex: bibliotecas de gráficos) | E10: Pode ocorrer bugs não resolvidos no dashboard | F10: O que acarretaria na qualidade do produto final que será comprometida, afetando a experiência do usuário | G10: Desenvolvedores | H10: Evitar | I10: Testar bibliotecas alternativas previamente | J10: Atualizar ou substituir bibliotecas | K10: Atraso no projeto e aumento nos custos | L10: 0.08 | O10: Moderada | P10: 3 | R10: Alta | S10: 4
A11: R07 | B11: Instalações | C11: Falhas | D11: Como resultado de falhas em infraestrutura de rede ou cloud durante o desenvolvimento | E11: Pode ocorrer atraso na conclusão do treinamento | F11: O que acarretaria na falta de sincronização | G11: Desenvolvedores | H11: Mitigar | I11: Usar múltiplos provedores de rede | J11: Trabalhar offline onde possível | K11: Atraso no projeto e aumento nos custos | L11: 0.08 | O11: Baixa | P11: 2 | R11: Moderada | S11: 3
A12: R08 | B12: Desenvolvimento | C12: Segurança | D12: Como resultado de vulnerabilidades no código | E12: Pode ocorrer breaches de dados de clientes | F12: O que acarretaria na privacidade dos dados violada, levando a problemas legais e perda de confiança | G12: Segurança | H12: Mitigar | I12: Implementar revisões de código regulares e testes de segurança | J12: Ativar backups e notificar stakeholders imediatamente | K12: Atraso no projeto e aumento nos custos | L12: 0.2 | O12: Moderada | P12: 3 | R12: Alta | S12: 4
A13: R09 | B13: Instalações | C13: Inadequação | D13: Como resultado de inadequação do ambiente de trabalho remoto (ex: conexões instáveis) | E13: Pode ocorrer baixa produtividade da equipe | F13: O que acarretaria em etapas como design e prototipagem serão atrasadas | G13: Gerência | H13: Mitigar | I13: Fornecer suporte técnico para setups remotos | J13: Ajustar horários flexíveis | K13: Atraso no projeto e aumento nos custos | L13: 0.16 | O13: Alta | P13: 4 | R13: Alta | S13: 4
A14: R10 | B14: Integração | C14: Integração falha | D14: Como resultado de incompatibilidades com sistemas de monitoramento de saúde | E14: Pode ocorrer falhas na importação de dados | F14: O que acarretaria na funcionalidade principal do dashboard comprometida | G14: Desenvolvedores | H14: Evitar | I14: Realizar testes de compatibilidade prévios | J14: Desenvolver APIs alternativas ou patches rápidos | K14: Atraso no projeto e aumento nos custos | L14: 0.08 | O14: Moderada | P14: 3 | R14: Moderada
A15: R11 | B15: Testes | C15: Qualidade baixa | D15: Como resultado de testes insuficientes | E15: Pode ocorrer lançamento com bugs críticos | F15: O que acarretaria nos usuários finais com problemas, afetando adoção | G15: Qualidade | H15: Mitigar | I15: Planejar ciclos de testes abrangentes | J15: Realizar rollout gradual com monitoramento | K15: Atraso no projeto e aumento nos custos | L15: 0.08 | O15: Baixa | P15: 2 | R15: Baixa | S15: 2
A16: R12 | B16: Marketing | C16: Adoção baixa | D16: Como resultado de estratégias de marketing ineficazes | E16: Pode ocorrer baixa adoção pelo mercado | F16: O que acarretaria no retorno sobre o investimento | G16: Marketing | H16: Evitar | I16: Monitorar métricas de campanhas | J16: Ajustar campanhas com base em feedback inicial | K16: Atraso no projeto e aumento nos custos | L16: 0.08 | O16: Alta | P16: 4 | R16: Alta | S16: 4
A17: R13 | B17: Expansão | C17: Mercado | D17: Como resultado de mudanças no mercado foodtech | E17: Pode ocorrer obsolescência rápida do dashboard | F17: O que acarretaria em novas funcionalidades necessárias prematuramente | G17: Gerência | H17: Transferir | I17: Manter análise de mercado contínua | J17: Parcerias para atualizações ágeis | K17: Atraso no projeto e aumento nos custos | L17: 0.08 | O17: Alta | P17: 4 | R17: Alta | S17: 4
A18: R14 | B18: Financeiro | C18: Orçamento | D18: Como resultado de subestimação de custos em recursos humanos | E18: Pode ocorrer overrun no orçamento | F18: O que acarretaria em recursos adicionais necessários, impactando viabilidade | G18: Gerência | H18: Mitigar | I18: Revisar estimativas periodicamente | J18: Re-alocar recursos internos | K18: Atraso no projeto e aumento nos custos | L18: 0.08 | O18: Moderada | P18: 3 | R18: Alta | S18: 4
A19: R15 | B19: Legal | C19: Compliance | D19: Como resultado de não conformidade com regulamentações de dados (ex: LGPD) | E19: Pode ocorrer multas ou bloqueios legais | F19: O que acarretaria no projeto suspenso | G19: Segurança | H19: Evitar | I19: Consultar especialistas em compliance desde o início | J19: Implementar correções e auditorias | K19: Atraso no projeto e aumento nos custos | L19: 0.2 | O19: Baixa | P19: 2 | R19: Moderada | S19: 3
A20: R16 | B20: Pessoas | C20: Motivação | D20: Como resultado de overload na equipe | E20: Pode ocorrer burnout e turnover | F20: O que acarretaria em perda de conhecimento e atrasos em etapas | G20: Gerência | H20: Mitigar | I20: Monitorar workload e promover equilíbrio | J20: Contratar freelancers temporários | K20: Atraso no projeto e aumento nos custos | L20: 0.08 | O20: Moderada | P20: 3 | R20: Moderada | S20: 3
A21: R17 | B21: Equipamentos | C21: Atualização | D21: Como resultado de atualizações incompatíveis em ferramentas de dev | E21: Pode ocorrer interrupções no fluxo de trabalho | F21: O que acarretaria na falta de produtividade | G21: Desenvolvedores | H21: Mitigar | I21: Testar atualizações em ambientes staging | J21: Rollback para versões estáveis | K21: Atraso no projeto e aumento nos custos | L21: 0.08 | O21: Alta | P21: 4 | R21: Alta | S21: 4
A22: R18 | B22: Instalações | C22: Pandemia | D22: Como resultado de restrições externas (ex: pandemia ou eventos globais) | E22: Pode ocorrer atrasos em reuniões presenciais ou entregas | F22: O que acarretaria na colaboração impactada, atrasando o cronograma | G22: Gerência | H22: Aceitar | I22: Planejar trabalho 100% remoto | J22: Extender prazos com aprovação de stakeholders | K22: Atraso no projeto e aumento nos custos | L22: 0.04 | O22: Alta | P22: 4 | R22: Alta | S22: 4
A23: R19 | B23: Marketing | C23: Concorrência | D23: Como resultado de ações de concorrentes | E23: Pode ocorrer perda de market share antes do lançamento | F23: O que acarretaria em estratégias de divulgação ajustadas | G23: Marketing | H23: Mitigar | I23: Análise competitiva regular | J23: Ajustar campanhas para destacar diferenciais | K23: Atraso no projeto e aumento nos custos | L23: 0.08 | O23: Moderada | P23: 3 | R23: Moderada | S23: 3
A24: R20 | B24: Avaliação | C24: Feedback negativo | D24: Como resultado de feedback inicial negativo | E24: Pode ocorrer necessidade de grandes revisões pós-lançamento | F24: O que acarretaria em aperfeiçoamentos que custarão mais tempo e recursos | G24: Comercial | H24: Mitigar | I24: Coletar feedback em betas | J24: Planejar iterações rápidas | K24: Atraso no projeto e aumento nos custos | L24: 0.08 | O24: Muito Baixa | P24: 1 | R24: Baixa | S24: 2
O25: Muito Baixa | P25: 1 | R25: Baixa | S25: 2
O26: Moderada | P26: 3 | R26: Moderada | S26: 3
O27: Moderada | P27: 3 | R27: Alta | S27: 4

Sheet Qualificar
A1: Qualificação dos Riscos | AF1: Probabilidade | AI1: Impacto
K2: Base Custo | M2: 10000 | N2: R$
K3: Base Prazo | M3: 30 | N3: dias úteis
A4: =#REF! -> #REF!
AF5: Muito Baixa - 1 | AG5: 1 | AI5: Muito Baixo - 1 | AJ5: 1
A6: ID | B6: Declaração do Risco | E6: Resp. | F6: Probabilidade do risco virar incidente (Y) | G6: Avaliação de Impacto (X) | K6: Severidade (Y,X) | M6: Custo | N6: Prazo | AF6: Baixa - 2 | AG6: 2 | AI6: Muito Baixo - 2 | AJ6: 2
B7: CAUSA (Começa a frase com "Como Resultado ...") | C7: RISCO (Começar a frase com "Pode ocorrer ...") | D7: CONSEQÜÊNCIA (Começar a frase com "O que acarretaria ...") | G7: Aumento no Custo (X1) | H7: Desvio no Cronograma (X2) | I7: (X1*X2) | J7: Resultado do Impacto (X1+X2) | L7: Riscos Colaterais | AF7: Moderada - 3 | AG7: 3 | AI7: Baixo - 3 | AJ7: 3
A8: R01 | B8: Como resultado da ausência de membros chave da equipe | C8: Pode ocorrer atrasos nas etapas de planejamento e desenvolvimento | D8: O cronograma do projeto será impactado, atrasando o lançamento | E8: GERENTE DE PROJETO | F8: Moderada - 0,2 | G8: Entre 10% e 20% - 1,40 | H8: Entre 10% e 20% - 2,40 | I8: 3.36 | J8: Moderada - 0,20 | K8: 0.08 | L8: Atraso no projeto e aumento nos custos | M8: =ROUNDUP(Quantificar!F8/Qualificar!$M$2,2) -> 1.24 | N8: =ROUNDUP(Quantificar!G8/Qualificar!$M$3,2) -> 0.47 | AF8: Alta - 4 | AG8: 4 | AI8: Baixo - 4 | AJ8: 4
A9: R02 | B9: Como resultado da falta de expertise em integração com sistemas de saúde | C9: Pode ocorrer falhas na integração de dados | D9: A sincronização de dados entre front-end e back-end falhará, comprometendo a usabilidade | E9: GERENTE DE PROJETO | F9: Alta - 0,4 | G9: Maior que 20% - 1,80 | H9: Entre 5% e 10% - 2,20 | I9: 4.32 | J9: =IF(I9<>"",VLOOKUP(I9,'Sensibilidade ao Risco'!$E$2:$F$30,2,FALSE),"") -> Muito Alta - 0,80 | K9: 0.16 | M9: 1.5 | N9: 0.2
A10: R03 | B10: Como resultado de desalinhamento de expectativas com stakeholders (ex: Cannoli e clientes) | C10: Pode ocorrer mudanças frequentes nos requisitos | D10: Re-trabalho no design e desenvolvimento, aumentando custos e prazos | E10: GERENTE DE PROJETO | F10: Muito Alta - 0,8 | G10: Entre 10% e 20% - 1,40 | H10: Entre 5% e 10% - 2,20 | I10: 3.08 | J10: =IF(I10<>"",VLOOKUP(I10,'Sensibilidade ao Risco'!$E$2:$F$30,2,FALSE),"") -> #N/A | K10: 0.12 | M10: 1.2 | N10: 0.15
A11: R04 | B11: Como resultado de roubo ou perda de equipamentos de desenvolvimento | C11: Pode ocorrer interrupção no desenvolvimento | D11: A equipe não poderá prosseguir com codificação e testes até reposição | E11: GERENTE DE PROJETO | F11: Baixa - 0,1 | G11: Entre 5% e 10% - 1,20 | H11: Entre 5% e 10% - 2,20 | I11: 2.64 | J11: =IF(I11<>"",VLOOKUP(I11,'Sensibilidade ao Risco'!$E$2:$F$30,2,FALSE),"") -> Alta - 0,40 | K11: 0.04 | M11: 0.8 | N11: 0.1
A12: R05 | B12: Como resultado de falha técnica em servidores ou ferramentas de desenvolvimento | C12: Pode ocorrer downtime durante o desenvolvimento e testes | D12: Atrasos em etapas críticas como integração e testes | E12: GERENTE DE PROJETO | F12: Moderada - 0,2 | G12: Entre 10% e 20% - 1,40 | H12: Entre 10% e 20% - 2,40 | I12: 3.08 | J12: =IF(I12<>"",VLOOKUP(I12,'Sensibilidade ao Risco'!$E$2:$F$30,2,FALSE),"") -> #N/A | K12: 0.08 | M12: =ROUNDUP(Quantificar!F12/Qualificar!$M$2,2) -> 1.24 | N12: 0.12
A13: R06 | B13: Como resultado de defeitos em softwares de terceiros (ex: bibliotecas de gráficos) | C13: Pode ocorrer bugs não resolvidos no dashboard | D13: A qualidade do produto final será comprometida, afetando a experiência do usuário | E13: GERENTE DE PROJETO | F13: Alta - 0,4 | G13: Entre 5% e 10% - 1,20 | H13: Entre 10% e 20% - 2,40 | I13: 2.88 | J13: =IF(I13<>"",VLOOKUP(I13,'Sensibilidade ao Risco'!$E$2:$F$30,2,FALSE),"") -> #N/A | K13: 0.12 | M13: 0.9 | N13: 0.15
A14: R07 | B14: Como resultado de falhas em infraestrutura de rede ou cloud durante o desenvolvimento | C14: Pode ocorrer interrupções na colaboração remota | D14: A equipe não conseguirá sincronizar código ou realizar reuniões efetivamente | E14: GERENTE DE PROJETO | F14: Moderada - 0,2 | G14: Entre 5% e 10% - 1,20 | H14: Menor que 5% - 2,10 | I14: 2.52 | J14: =IF(I14<>"",VLOOKUP(I14,'Sensibilidade ao Risco'!$E$2:$F$30,2,FALSE),"") -> #N/A | K14: 0.08 | M14: 0.7 | N14: 0.08
A15: R08 | B15: Como resultado de inadequação do ambiente de trabalho remoto | C15: Pode ocorrer baixa produtividade da equipe | D15: Etapas como design e prototipagem serão atrasadas | E15: GERENTE DE PROJETO | F15: Baixa - 0,1 | G15: Menor que 5% - 1,10 | H15: Menor que 5% - 2,10 | I15: 2.31 | J15: Baixa - 0,10 | K15: 0.06 | M15: 0.6 | N15: 0.07
A16: R09 | B16: Como resultado de vulnerabilidades no código | C16: Pode ocorrer breaches de dados de clientes | D16: A privacidade dos dados será violada, levando a problemas legais e perda de confiança | E16: GERENTE DE PROJETO | F16: Alta - 0,4 | G16: Maior que 20% - 1,80 | H16: Maior que 20% - 2,80 | I16: 5.04 | J16: =IF(I16<>"",VLOOKUP(I16,'Sensibilidade ao Risco'!$E$2:$F$30,2,FALSE),"") -> #N/A | K16: 0.2 | M16: 2 | N16: 0.3
A17: R10 | B17: Como resultado de incompatibilidades com sistemas de monitoramento de saúde | C17: Pode ocorrer falhas na importação de dados | D17: A funcionalidade principal do dashboard será comprometida | E17: GERENTE DE PROJETO | F17: Alta - 0,4 | G17: Entre 10% e 20% - 1,40 | H17: Entre 10% e 20% - 2,40 | I17: 3.36 | J17: =IF(I17<>"",VLOOKUP(I17,'Sensibilidade ao Risco'!$E$2:$F$30,2,FALSE),"") -> #N/A | K17: 0.16 | M17: 1.5 | N17: 0.2
A18: R11 | B18: Como resultado de testes insuficientes | C18: Pode ocorrer lançamento com bugs críticos | D18: Usuários finais enfrentarão problemas, afetando adoção | E18: QUALIDADE | F18: Moderada - 0,2 | G18: Entre 5% e 10% - 1,20 | H18: Entre 10% e 20% - 2,40 | I18: 2.88 | J18: =IF(I18<>"",VLOOKUP(I18,'Sensibilidade ao Risco'!$E$2:$F$30,2,FALSE),"") -> #N/A | K18: 0.12 | M18: 1 | N18: 0.15
A19: R12 | B19: Como resultado de estratégias de marketing ineficazes | C19: Pode ocorrer baixa adoção pelo mercado | D19: O retorno sobre o investimento será reduzido | E19: EQUIPE TÉCNICA | F19: Baixa - 0,1 | G19: Menor que 5% - 1,10 | H19: Entre 5% e 10% - 2,20 | I19: 2.42 | J19: Moderada - 0,20 | K19: 0.08 | M19: 0.8 | N19: 0.1
A20: R13 | B20: Como resultado de mudanças no mercado foodtech | C20: Pode ocorrer obsolescência rápida do dashboard | D20: Novas funcionalidades serão necessárias prematuramente | E20: GERENTE DE PROJETO | F20: Moderada - 0,2 | G20: Entre 5% e 10% - 1,20 | H20: Menor que 5% - 2,10 | I20: 2.52 | J20: =IF(I20<>"",VLOOKUP(I20,'Sensibilidade ao Risco'!$E$2:$F$30,2,FALSE),"") -> #N/A | K20: 0.1 | M20: 0.9 | N20: 0.12
A21: R14 | B21: Como resultado de subestimação de custos em recursos humanos | C21: Pode ocorrer overrun no orçamento | D21: Recursos adicionais serão necessários, impactando viabilidade | E21: GERENTE DE PROJETO | F21: Alta - 0,4 | G21: Entre 10% e 20% - 1,40 | H21: Insignificante - 2,05 | I21: 2.87 | J21: Alta - 0,40 | K21: 0.15 | M21: 1.2 | N21: 0.1
A22: R15 | B22: Como resultado de não conformidade com regulamentações de dados | C22: Pode ocorrer multas ou bloqueios legais | D22: O projeto pode ser suspenso | E22: SEGURANÇA | F22: Muito Alta - 0,8 | G22: Maior que 20% - 1,80 | H22: Maior que 20% - 2,80 | I22: 5.04 | J22: =IF(I22<>"",VLOOKUP(I22,'Sensibilidade ao Risco'!$E$2:$F$30,2,FALSE),"") -> #N/A | K22: 0.2 | M22: 2.5 | N22: 0.4
A23: R16 | B23: Como resultado de overload na equipe | C23: Pode ocorrer burnout e turnoversos em etapas | D23: Perda de conhecimento e atra | E23: GERENTE DE PROJETO | F23: Moderada - 0,2 | G23: Entre 5% e 10% - 1,20 | H23: Entre 5% e 10% - 2,20 | I23: 2.64 | J23: =IF(I23<>"",VLOOKUP(I23,'Sensibilidade ao Risco'!$E$2:$F$30,2,FALSE),"") -> Alta - 0,40 | K23: 0.1 | M23: 1 | N23: 0.12
A24: R17 | B24: Como resultado de atualizações incompatíveis em ferramentas de dev | C24: Pode ocorrer interrupções no fluxo de trabalho | D24: A produtividade cairá durante transições | E24: DESENVOLVIMENTO | F24: Baixa - 0,1 | G24: Menor que 5% - 1,10 | H24: Menor que 5% - 2,10 | I24: 2.31 | J24: Baixa - 0,10 | K24: 0.08 | M24: 0.7 | N24: 0.08
A25: R18 | B25: Como resultado de restrições externas (ex: pandemia ou eventos globais) | C25: Pode ocorrer atrasos em reuniões presenciais ou entregas | D25: Colaboração será impactada, atrasando o cronograma | E25: GERENTE DE PROJETO | F25: Muito baixa - 0,05 | G25: Insignificante - 1,05 | H25: Insignificante - 2,05 | I25: 2.15 | J25: Muito Baixa - 0,05 | K25: 0.05 | M25: 0.5 | N25: 0.05
A26: R19 | B26: Como resultado de ações de concorrentes | C26: Pode ocorrer perda de market share antes do lançamento | D26: Estratégias de divulgação precisarão ser ajustadas | E26: EQUIPE TÉCNICA | F26: Moderada - 0,2 | G26: Entre 5% e 10% - 1,20 | H26: Entre 5% e 10% - 2,20 | I26: 2.64 | J26: =IF(I26<>"",VLOOKUP(I26,'Sensibilidade ao Risco'!$E$2:$F$30,2,FALSE),"") -> Alta - 0,40 | K26: 0.12 | M26: 0.9 | N26: 0.1
A27: R20 | B27: Como resultado de feedback inicial negativo | C27: Pode ocorrer necessidade de grandes revisões pós-lançamento | D27: Aperfeiçoamentos custarão mais tempo e recursos | E27: COMERCIAL | F27: Moderada - 0,2 | G27: Menor que 5% - 1,10 | H27: Entre 10% e 20% - 2,40 | I27: 2.64 | J27: =IF(I27<>"",VLOOKUP(I27,'Sensibilidade ao Risco'!$E$2:$F$30,2,FALSE),"") -> Alta - 0,40 | K27: 0.1 | M27: 0.8 | N27: 0.15
F47: Insignificante - 1,05 | G47: Insignificante - 2,05 | H47: Muito baixa - 0,05
F48: Menor que 5% - 1,10 | G48: Menor que 5% - 2,10 | H48: Baixa - 0,1
F49: Entre 5% e 10% - 1,20 | G49: Entre 5% e 10% - 2,20 | H49: Moderada - 0,2
F50: Entre 10% e 20% - 1,40 | G50: Entre 10% e 20% - 2,40 | H50: Alta - 0,4
F51: Maior que 20% - 1,80 | G51: Maior que 20% - 2,80 | H51: Muito Alta - 0,8

Sheet Quantificar
A1: Quantificação dos Riscos | AA1: Probabilidade | AD1: Impacto
A4: =#REF! -> #REF!
AA5: Muito Baixa - 1 | AB5: 1 | AD5: Muito Baixo - 1 | AE5: 1
A6: ID | B6: Declaração do Risco | E6: Resp. | F6: Impacto no Custo (Considerar qtde. de horas como unidade de medida, inclusive, a maior ou menor) | G6: Impacto no Cronograma (Colocar qtde. de dias de redução ou atraso no cronograma) | H6: Observação | I6: Plano de Prevenção | J6: Plano de Contingência | AA6: Baixa - 2 | AB6: 2 | AD6: Muito Baixo - 2 | AE6: 2
B7: CAUSA (Começa a frase com "Como Resultado ...") | C7: RISCO (Começar a frase com "Pode ocorrer ...") | D7: CONSEQÜÊNCIA (Começar a frase com "O que acarretaria ...") | AA7: Moderada - 3 | AB7: 3 | AD7: Baixo - 3 | AE7: 3
A8: R01 | B8: Como resultado da ausência de membros chave da equipe | C8: Pode ocorrer atrasos nas etapas de planejamento e desenvolvimento | D8: O cronograma do projeto será impactado, atrasando o lançamento | E8: GERENTE DE PROJETO | F8: 12340 | G8: 14 | H8: Dias de atraso no desenvolvimento | I8: Implementar cross-training na equipe | J8: Contratar substitutos temporários | AA8: Alta - 4 | AB8: 4 | AD8: Baixo - 4 | AE8: 4
A9: R02 | B9: Como resultado da falta de expertise em integração com sistemas de saúde | C9: Pode ocorrer falhas na integração de dados | D9: A sincronização de dados entre front-end e back-end falhará, comprometendo a usabilidade | E9: GERENTE DE PROJETO | F9: 18510 | G9: 24 | H9: Dias de atraso na integração | I9: Contratar consultores especializados | J9: Realizar treinamentos acelerados
A10: R03 | B10: Como resultado de desalinhamento de expectativas com stakeholders | C10: Pode ocorrer mudanças frequentes nos requisitos | D10: Re-trabalho no design e desenvolvimento, aumentando custos e prazos | E10: GERENTE DE PROJETO | F10: 14808 | G10: 18 | H10: Dias de re-trabalho | I10: Realizar reuniões de alinhamento regulares | J10: Documentar mudanças e priorizar via PO
A11: R04 | B11: Como resultado de roubo ou perda de equipamentos de desenvolvimento | C11: Pode ocorrer interrupção no desenvolvimento | D11: A equipe não poderá prosseguir com codificação e testes até reposição | E11: GERENTE DE PROJETO | F11: 9872 | G11: 12 | H11: Dias para reposição | I11: Seguros e backups em cloud | J11: Fornecer equipamentos de backup
A12: R05 | B12: Como resultado de falha técnica em servidores ou ferramentas de desenvolvimento | C12: Pode ocorrer downtime durante o desenvolvimento e testes | D12: Atrasos em etapas críticas como integração e testes | E12: GERENTE DE PROJETO | F12: 12340 | G12: 14 | H12: Dias de downtime | I12: Manutenção preventiva em servidores | J12: Migrar para provedores redundantes
A13: R06 | B13: Como resultado de defeitos em softwares de terceiros | C13: Pode ocorrer bugs não resolvidos no dashboard | D13: A qualidade do produto final será comprometida, afetando a experiência do usuário | E13: GERENTE DE PROJETO | F13: 11106 | G13: 18 | H13: Dias para depuração | I13: Testar bibliotecas alternativas previamente | J13: Atualizar ou substituir bibliotecas
A14: R07 | B14: Como resultado de falhas em infraestrutura de rede ou cloud durante o desenvolvimento | C14: Pode ocorrer interrupções na colaboração remota | D14: A equipe não conseguirá sincronizar código ou realizar reuniões efetivamente | E14: GERENTE DE PROJETO | F14: 8638 | G14: 10 | H14: Dias de interrupção | I14: Usar múltiplos provedores de rede | J14: Trabalhar offline onde possível
A15: R08 | B15: Como resultado de inadequação do ambiente de trabalho remoto | C15: Pode ocorrer baixa produtividade da equipe | D15: Etapas como design e prototipagem serão atrasadas | E15: GERENTE DE PROJETO | F15: 7404 | G15: 8 | H15: Dias de baixa produtividade | I15: Fornecer suporte técnico para setups remotos | J15: Ajustar horários flexíveis
A16: R09 | B16: Como resultado de vulnerabilidades no código | C16: Pode ocorrer breaches de dados de clientes | D16: A privacidade dos dados será violada, levando a problemas legais e perda de confiança | E16: GERENTE DE PROJETO | F16: 24680 | G16: 36 | H16: Dias para recuperação legal | I16: Implementar revisões de código regulares e testes de segurança | J16: Ativar backups e notificar stakeholders imediatamente
A17: R10 | B17: Como resultado de incompatibilidades com sistemas de monitoramento de saúde | C17: Pode ocorrer falhas na importação de dados | D17: A funcionalidade principal do dashboard será comprometida | E17: GERENTE DE PROJETO | F17: 18510 | G17: 24 | H17: Dias para correções | I17: Realizar testes de compatibilidade prévios | J17: Desenvolver APIs alternativas ou patches rápidos
A18: R11 | B18: Como resultado de testes insuficientes | C18: Pode ocorrer lançamento com bugs críticos | D18: Usuários finais enfrentarão problemas, afetando adoção | E18: QUALIDADE | F18: 12340 | G18: 18 | H18: Dias para fixes pós-lançamento | I18: Planejar ciclos de testes abrangentes | J18: Realizar rollout gradual com monitoramento
A19: R12 | B19: Como resultado de estratégias de marketing ineficazes | C19: Pode ocorrer baixa adoção pelo mercado | D19: O retorno sobre o investimento será reduzido | E19: EQUIPE TÉCNICA | F19: 9872 | G19: 12 | H19: Dias para ajustes de campanha | I19: Monitorar métricas de campanhas | J19: Ajustar campanhas com base em feedback inicial
A20: R13 | B20: Como resultado de mudanças no mercado foodtech | C20: Pode ocorrer obsolescência rápida do dashboard | D20: Novas funcionalidades serão necessárias prematuramente | E20: GERENTE DE PROJETO | F20: 11106 | G20: 14 | H20: Dias para atualizações | I20: Manter análise de mercado contínua | J20: Parcerias para atualizações ágeis
... A27: R20 | B27: Como resultado de feedback inicial negativo | C27: Pode ocorrer necessidade de grandes revisões pós-lançamento | D27: Aperfeiçoamentos custarão mais tempo e recursos | E27: COMERCIAL | F27: 9872 | G27: 18 | H27: Dias para iterações | I27: Coletar feedback em betas | J27: Planejar iterações rápidas

Sheet Histórico de evolução(não)
A1: Não precisa preencher, pois o projeto não será acompanhado.
A2: Versão | B2: Autor | C2: Id Risco | D2: Categoria | E2: Data | F2: Situação anterior | G2: Situação Atual | H2: Motivo
A3: 1 | C3: R01 | E3: 39511 | F3: 0 | G3: 0.32 | H3: Levantamento inicial
A4: 1 | C4: R02 | E4: 39511 | F4: 0 | G4: 0.005 | H4: Levantamento inicial
A5: 1 | C5: R03 | E5: 39511 | F5: 0 | G5: 0.01 | H5: Levantamento inicial
A6: 1 | C6: R04 | E6: 39511 | F6: 0 | G6: 0.02 | H6: Levantamento inicial
A7: 1 | C7: R05 | E7: 39511 | F7: 0 | G7: 0.02 | H7: Levantamento inicial
A8: 1 | C8: R06 | E8: 39511 | F8: 0 | G8: 0.02 | H8: Levantamento inicial
A9: 1 | C9: R07 | E9: 39511 | F9: 0 | G9: 0.04 | H9: Levantamento inicial
A10: 1 | C10: R08 | E10: 39511 | F10: 0 | G10: 0.01 | H10: Levantamento inicial
A11: 1 | C11: R09 | E11: 39511 | F11: 0 | G11: 0.04 | H11: Levantamento inicial
A12: 1 | C12: R10 | E12: 39511 | F12: 0 | G12: 0.005 | H12: Levantamento inicial
A13: 1 | C13: R11 | E13: 39511 | F13: 0 | G13: 0.01 | H13: Levantamento inicial
A14: 1 | C14: R12 | E14: 39511 | F14: 0 | G14: 0.02 | H14: Levantamento inicial
A15: 1 | C15: R13 | E15: 39511 | F15: 0 | G15: 0.04 | H15: Levantamento inicial

Sheet Sensibilidade ao Risco
A1: Custo | B1: Peso1 | C1: Cronograma | D1: Peso2 | E1: Peso1 X Peso2 | F1: Impacto
A2: Ausência de membros chave | B2: 1.20 | C2: Desvio total 10–20% | D2: 2.40 | E2: 2.88 | F2: Alta - 0,40
A3: Falta de expertise técnica | B3: 1.40 | C3: Desvio total 10–20% | D3: 2.40 | E3: 3.36 | F3: Alta - 0,40
A4: Desalinhamento com stakeholders | B4: 1.20 | C4: Desvio total 5–10% | D4: 2.2 | E4: 2.64 | F4: Alta - 0,40
A5: Aumento de custo Insignificante | B5: 1.05 | C5: Desvio <5% | D5: 2.10 | E5: 2.21 | F5: Baixa - 0,10
A6: Aumento de custo Insignificante | B6: 1.10 | C6: Desvio total 10–20% | D6: 2.40 | E6: 2.64 | F6: Alta - 0,40
A8: Roubo/perda de equipamentos | B8: 01.05 | C8: Desvio <5% | D8: 2.10 | E8: 2.21 | F8: Muito baixa - 0,05
A9: Falha técnica em servidores | B9: 1.10 | C9: Desvio total 10–20% | D9: 2.40 | E9: 2.64 | F9: Alta - 0,40
A10: Defeitos em bibliotecas externas | B10: 1.1 | C10: Desvio total 10–20% | D10: 2.40 | E10: 2.88 | F10: Alta - 0,40
A11: Falha de infraestrutura cloud | B11: 1.1 | C11: Desvio total 5–10% | D11: 2.4 | E11: 2.64 | F11: Alta - 0,40
A12: Ambiente remoto inadequado | B12: 01.05 | C12: Desvio total 5–10% | D12: 2.20 | E12: 2.31 | F12: Baixa - 0,10
A14: Vulnerabilidade de segurança | B14: 1.80 | C14: Desvio total 10–20% | D14: 2.40 | E14: 4.32 | F14: Alta - 0,40
A15: Falha na integração de sistemas | B15: 1.40 | C15: Desvio total 10–20% | D15: 2.40 | E15: 3.36 | F15: Alta - 0,40
A16: Testes insuficientes | B16: 1.20 | C16: Desvio total 10–20% | D16: 2.40 | E16: 2.88 | F16: Alta - 0,40
A17: Baixa adoção pelo mercado | B17: 01.05 | C17: Desvio >20% | D17: 2.80 | E17: 2.94 | F17: Alta - 0,40
A18: Mudanças no mercado foodtech | B18: 1.10 | C18: Desvio total 10–20% | D18: 2.40 | E18: 2.64 | F18: Alta - 0,40
A20: Estouro de orçamento | B20: 1.80 | C20: Desvio total 5–10% | D20: 2.20 | E20: 3.96 | F20: Alta - 0,40
A21: Não conformidade com LGPD | B21: 1.80 | C21: Desvio >20% | D21: 2.80 | E21: 05.04 | F21: Alta - 0,40
A22: Burnout da equipe | B22: 1.20 | C22: Desvio total 5–10% | D22: 2.20 | E22: 2.64 | F22: Alta - 0,40
A23: Atualizações incompatíveis | B23: 1.10 | C23: Desvio total 5–10% | D23: 2.20 | E23: 2.42 | F23: Moderada - 0,20
A24: Restrições externas (pandemia) | B24: 01.05 | C24: Desvio total 10–20% | D24: 2.40 | E24: 2.52 | F24: Moderada - 0,20
A26: Ações da concorrência | B26: 1.20 | C26: Desvio total 5–10% | D26: 2.20 | E26: 2.64 | F26: Alta - 0,40
A27: Feedback negativo pós-lançamento | B27: 1.40 | C27: Desvio total 10–20% | D27: 2.40 | E27: 3.36 | F27: Alta - 0,40
A28: Mais de 20% de aumento nos custos | B28: 1.8 | C28: Desvio total 5–10% | D28: 2.2 | E28: 3.96 | F28: Muito Alta - 0,80
A29: Mais de 20% de aumento nos custos | B29: 1.8 | C29: Desvio total 10–20% | D29: 2.4 | E29: 4.32 | F29: Muito Alta - 0,80
A30: Mais de 20% de aumento nos custos | B30: 1.8 | C30: Desvio total >20% | D30: 1.80 | E30: 05.04 | F30: Muito Alta - 0,80
A32: Muito baixa - 0,05
A33: Baixa - 0,10
A34: Moderada - 0,20
A35: Alta - 0,40
A36: Muito Alta - 0,80

Sheet Gestão de Custo
B2: Previsões de Orçamento | J2: Saúde e Bem Estar
C4: 1 | D4: Capa | F4: Instruções, Histórico de Alterações e as Aprovações
C5: =C4+1 -> 2 | D5: Orçado | F5: Detalhamento dos investimentos orçados
C6: =C5+1 -> 3 | D6: Realizado | F6: Detalhamento dos investimentos realizados
C7: =C6+1 -> 4 | D7: Status | F7: Status comparando Orçado x Realizado
C8: =C7+1 -> 5 | D8: Parâmetros | F8: Parâmetros usados nas outras abas da planilha.
D10: Fonte | E10: https://escritoriodeprojetos.com.br/download/previsoes-do-orcamento/
B14: Controle de Versões
B15: Versão | C15: Data | D15: Autor | E15: Notas da Revisão
B16: 1 | C16: 45906 | D16: Bruna Farias
B17: 2 | C17: 45907 | D17: Anie Bissoli
B18: 3 | C18: 45908 | D18: Erika Santana
B19: 4 | C19: 45909 | D19: Luiza Correa
B21: Instruções | D21: =TODAY() -> 45971
B22: Ref. | C22: Aba | D22: Respons | E22: Passos
B23: 0 | C23: Param | D23: PMO | E23: Inserir o custo do capital.
B24: 1 | C24: Orçado | D24: Gerente de Projetos | E24: Preencher as informações de identificação do projeto (Nome: Dashboard Interativo; Solicitante: Comercial; Patrocinador: Diretoria Técnica)
B25: =B24+1 -> 2 | C25: Orçado | D25: Gerente de Projetos | E25: Listar os gastos (Design, Desenvolvimento, Testes, etc.).
B26: =B25+1 -> 3 | C26: Orçado | D26: Gerente de Projetos | E26: Sempre que possível, esclarecer como foi calculado o valor dos gastos
B27: =B26+1 -> 4 | C27: Orçado | D27: Gerente de Projetos | E27: Informar valores por ano ou crescimento anual.
B28: =B27+1 -> 5 | C28: Orçado | D28: Gerente de Projetos | E28: Custos administrativos/indiretos: nome, cálculo e valores por ano.
B29: =B28+1 -> 6 | C29: Orçado | D29: Gerente de Projetos | E29: Sempre que possível, esclarecer como foi calculado o valor dos custos indiretos
B30: =B29+1 -> 7 | C30: Orçado | D30: Gerente de Projetos | E30: Entrar com os valores dos custos indiretos por ano
B31: =B30+1 -> 8 | C31: Realizado | D31: Gerente de Projetos | E31: Preencher valores realizados mês a mês.
B32: =B31+1 -> 9 | C32: Status | D32: Gerente de Projetos | E32: Verificar diferenças entre valores orçados e realizados automaticamente. Avaliar variações significativas.
B33: =B32+1 -> 10 | C33: Status | D33: Gerente de Projetos | E33: Justificar variações acima de 10% entre o planejado e o realizado nas colunas de observações.
B34: =B33+1 -> 11 | C34: Param | D34: PMO | E34: Validar tipos de gasto e atualizar parâmetros conforme mudanças de cenário.
B36: Aprovações
B37: Ref. | C37: Data | D37: Participante | E37: Assinatura
B38: 1 | C38: 45936 | D38: Bruna Farias | E38: BRUNA
B39: 2 | C39: 45937 | D39: Anie Bissoli | E39: ANIE
B40: 3 | C40: 45938 | D40: Erika Santana | E40: ERIKA
B41: 4 | C41: 45938 | D41: Luiza Correa | E41: LUIZA

Sheet Orcado
B2: Identificação do Projeto | D2: Mês
B3: Nome do Projeto | C3: =Param!C17 -> Elevare | E3: =Param!C18 -> 45983 | F3: =DATE(YEAR(E3),MONTH(E3)+1,DAY(E3)) -> 46013 | G3: =DATE(YEAR(F3),MONTH(F3)+1,DAY(F3)) -> 46044 | H3: =DATE(YEAR(G3),MONTH(G3)+1,DAY(G3)) -> 46075 | I3: =DATE(YEAR(H3),MONTH(H3)+1,DAY(H3)) -> 46103 | J3: =DATE(YEAR(I3),MONTH(I3)+1,DAY(I3)) -> 46134 | K3: =DATE(YEAR(J3),MONTH(J3)+1,DAY(J3)) -> 46164 | L3: =DATE(YEAR(K3),MONTH(K3)+1,DAY(K3)) -> 46195 | M3: =DATE(YEAR(L3),MONTH(L3)+1,DAY(L3)) -> 46225 | ... P3: =DATE(YEAR(O3),MONTH(O3)+1,DAY(O3)) -> 46317 | Q3: TOTAL
B4: Patrocinador | C4: =Param!C19 -> FECAP | D4: 0 | E4: 1 | F4: =E4+1 -> 2 | G4: =F4+1 -> 3 | H4: =G4+1 -> 4 | I4: =H4+1 -> 5 | J4: =I4+1 -> 6 | K4: =J4+1 -> 7 | L4: =K4+1 -> 8 | M4: =L4+1 -> 9 | ... P4: =O4+1 -> 12
